Workbook
Name BurndownDates: 'Burndown Chart'!$B$26:INDEX('Burndown Chart'!$B:$B,25+COUNT('Burndown Chart'!$A$26:$A$119))
Name BurndownRemaining: 'Burndown Chart'!$C$26:INDEX('Burndown Chart'!$C:$C,25+COUNT('Burndown Chart'!$A$26:$A$119))

Sheet Product Backlog
A1: Product Backlog
A4: Task # | B4: Sprint # | C4: Task description | D4: Status | E4: Maintainer | F4: Date added | G4: Date completed | H4: Hours to complete | I4: Work points assigned | J4: Sprint view key
A5: 1 | B5: 1 | C5: Basic webpage and repo setup | D5: Done | E5: chropic | F5: 46274 | G5: 46276 | H5: 0.5 | I5: 25 | J5: =IF(OR(B5="",C5=""),"",B5&"-"&COUNTIFS($B$5:B5,B5,$C$5:C5,"<>")) -> 1-1
A6: 2 | B6: 1 | C6: Actual web interface and demo features | D6: Done | E6: oogwaysprophecy732 | F6: 46274 | G6: 46281 | H6: 2 | I6: 55 | J6: =IF(OR(B6="",C6=""),"",B6&"-"&COUNTIFS($B$5:B6,B6,$C$5:C6,"<>")) -> 1-2
A7: 3 | B7: 1 | C7: Find client and update README | D7: Done | E7: chropic | F7: 46274 | G7: 46283 | H7: 1 | I7: 15 | J7: =IF(OR(B7="",C7=""),"",B7&"-"&COUNTIFS($B$5:B7,B7,$C$5:C7,"<>")) -> 1-3
A8: 4 | B8: 2 | C8: German language toggle | D8: Completed | E8: chropic | F8: 46288 | G8: 46293 | H8: 2.5 | I8: 45 | J8: =IF(OR(B8="",C8=""),"",B8&"-"&COUNTIFS($B$5:B8,B8,$C$5:C8,"<>")) -> 2-1
A9: 5 | B9: 2 | C9: Updated Search Feature (Frontend) | D9: Completed | E9: oogwaysprophecy732 | F9: 46288 | G9: 46288 | H9: 2 | I9: 45 | J9: =IF(OR(B9="",C9=""),"",B9&"-"&COUNTIFS($B$5:B9,B9,$C$5:C9,"<>")) -> 2-2
A10: 6 | B10: 2 | C10: Server-side RSS Feed | D10: Completed | E10: chropic | F10: 46288 | G10: 46295 | H10: 3 | I10: 50 | J10: =IF(OR(B10="",C10=""),"",B10&"-"&COUNTIFS($B$5:B10,B10,$C$5:C10,"<>")) -> 2-3
A11: 7 | B11: 3 | C11: Define bias detection-what does bias look like (research included) | D11: Completed | E11: chropic & oogwaysprophecy732 | F11: 46302 | G11: 46309 | H11: 2 | I11: 75 | J11: =IF(OR(B11="",C11=""),"",B11&"-"&COUNTIFS($B$5:B11,B11,$C$5:C11,"<>")) -> 3-1
A12: 8 | B12: 3 | C12: RSS Filtering | D12: Completed | E12: oogwaysprophecy732 | F12: 46302 | G12: 46309 | H12: 3 | I12: 50 | J12: =IF(OR(B12="",C12=""),"",B12&"-"&COUNTIFS($B$5:B12,B12,$C$5:C12,"<>")) -> 3-2
A13: 9 | B13: 3 | C13: Updated UI | D13: Completed | E13: chropic | F13: 46302 | G13: 46304 | H13: 1.5 | I13: 35 | J13: =IF(OR(B13="",C13=""),"",B13&"-"&COUNTIFS($B$5:B13,B13,$C$5:C13,"<>")) -> 3-3
C14: Prototype bias detection model | D14: Backlog | I14: 150 | J14: =IF(OR(B14="",C14=""),"",B14&"-"&COUNTIFS($B$5:B14,B14,$C$5:C14,"<>"))
C15: Stable increment of bias detection model | D15: Backlog | I15: 200 | J15: =IF(OR(B15="",C15=""),"",B15&"-"&COUNTIFS($B$5:B15,B15,$C$5:C15,"<>"))
C16: Implement bias detection model into search feature | D16: Backlog | I16: 150 | J16: =IF(OR(B16="",C16=""),"",B16&"-"&COUNTIFS($B$5:B16,B16,$C$5:C16,"<>"))
C17: Better UX with distinct language (close to/final sprint) | D17: Backlog | I17: 50 | J17: =IF(OR(B17="",C17=""),"",B17&"-"&COUNTIFS($B$5:B17,B17,$C$5:C17,"<>"))
C18: Fine tune Docker container performance options, resource limits, security hardenings. | D18: Backlog | I18: 10 | J18: =IF(OR(B18="",C18=""),"",B18&"-"&COUNTIFS($B$5:B18,B18,$C$5:C18,"<>"))
C19: Server-side optimizations and hardenings | D19: Backlog | I19: 35 | J19: =IF(OR(B19="",C19=""),"",B19&"-"&COUNTIFS($B$5:B19,B19,$C$5:C19,"<>"))
C20: Website name and branding(?) | D20: Backlog | I20: 15 | J20: =IF(OR(B20="",C20=""),"",B20&"-"&COUNTIFS($B$5:B20,B20,$C$5:C20,"<>"))
J21: =IF(OR(B21="",C21=""),"",B21&"-"&COUNTIFS($B$5:B21,B21,$C$5:C21,"<>"))
J22: =IF(OR(B22="",C22=""),"",B22&"-"&COUNTIFS($B$5:B22,B22,$C$5:C22,"<>"))
J23: =IF(OR(B23="",C23=""),"",B23&"-"&COUNTIFS($B$5:B23,B23,$C$5:C23,"<>"))
J24: =IF(OR(B24="",C24=""),"",B24&"-"&COUNTIFS($B$5:B24,B24,$C$5:C24,"<>"))
J25: =IF(OR(B25="",C25=""),"",B25&"-"&COUNTIFS($B$5:B25,B25,$C$5:C25,"<>"))
J26: =IF(OR(B26="",C26=""),"",B26&"-"&COUNTIFS($B$5:B26,B26,$C$5:C26,"<>"))
J27: =IF(OR(B27="",C27=""),"",B27&"-"&COUNTIFS($B$5:B27,B27,$C$5:C27,"<>"))
J28: =IF(OR(B28="",C28=""),"",B28&"-"&COUNTIFS($B$5:B28,B28,$C$5:C28,"<>"))
J29: =IF(OR(B29="",C29=""),"",B29&"-"&COUNTIFS($B$5:B29,B29,$C$5:C29,"<>"))
J30: =IF(OR(B30="",C30=""),"",B30&"-"&COUNTIFS($B$5:B30,B30,$C$5:C30,"<>"))
J31: =IF(OR(B31="",C31=""),"",B31&"-"&COUNTIFS($B$5:B31,B31,$C$5:C31,"<>"))
J32: =IF(OR(B32="",C32=""),"",B32&"-"&COUNTIFS($B$5:B32,B32,$C$5:C32,"<>"))
... J504: =IF(OR(B504="",C504=""),"",B504&"-"&COUNTIFS($B$5:B504,B504,$C$5:C504,"<>"))

Sheet Burndown Chart
A1: Project Burndown | Sprints 1–6 | B1: Project Burndown | Sprints 1–6 | C1: Project Burndown | Sprints 1–6 | D1: Project Burndown | Sprints 1–6 | E1: Project Burndown | Sprints 1–6 | F1: Project Burndown | Sprints 1–6 | G1: Project Burndown | Sprints 1–6 | H1: Project Burndown | Sprints 1–6 | I1: Project Burndown | Sprints 1–6 | J1: Project Burndown | Sprints 1–6 | K1: Project Burndown | Sprints 1–6 | L1: Project Burndown | Sprints 1–6 | M1: Project Burndown | Sprints 1–6
A2: Remaining work units are calculated from Product Backlog completion dates and work points. The chart stops at the latest qualifying completion date.
K4: Sprint | L4: Start date | M4: End date
K5: 1 | L5: ='Sprint 1'!$E$4 -> 46274 | M5: ='Sprint 1'!$H$4 -> 46283
K6: 2 | L6: ='Sprint 2'!$E$4 -> 46288 | M6: ='Sprint 2'!$H$4 -> 46297
K7: 3 | L7: ='Sprint 3'!$E$4 -> 46302 | M7: ='Sprint 3'!$H$4 -> 46311
K8: 4 | L8: ='Sprint 4'!$E$4 -> 46316 | M8: ='Sprint 4'!$H$4 -> 46325
K9: 5 | L9: ='Sprint 5'!$E$4 -> 46330 | M9: ='Sprint 5'!$H$4 -> 46339
K10: 6 | L10: ='Sprint 6'!$E$4 -> 46344 | M10: ='Sprint 6'!$H$4 -> 46358
K13: Starting work units | L13: 1000
K14: All work points assigned | L14: =SUM('Product Backlog'!$I$5:$I$504) -> 1005
K15: Completed points recorded | L15: =SUMIFS('Product Backlog'!$I$5:$I$504,'Product Backlog'!$G$5:$G$504,">0",'Product Backlog'!$I$5:$I$504,">0") -> 395
K16: Remaining work units now | L16: =MAX(0,L13-L15) -> 605
K17: Chart through | L17: =IF(COUNTIFS('Product Backlog'!$G$5:$G$504,">0",'Product Backlog'!$I$5:$I$504,">=0",'Product Backlog'!$I$5:$I$504,"<>")=0,'Sprint 1'!$E$4,MAX(_xlfn._xlws.FILTER('Product Backlog'!$G$5:$G$504,('Product Backlog'!$G$5:$G$504>0)*('Product Backlog'!$I$5:$I$504>=0)*('Product Backlog'!$I$5:$I$504<>""),'Sprint 1'!$E$4))) -> 46309
A25: Date | B25: Sprint or completion label | C25: Remaining work units | D25: Completed work points | P25: Sprint / completed date | Q25: Remaining work units | R25: Ideal remaining work units
A26: =$L$5+0 -> 46274 | B26: =IF(A26=$L$5,"Sprint 1 ("&TEXT(A26,"m/d")&")",IF(A26=$L$6,"Sprint 2 ("&TEXT(A26,"m/d")&")",IF(A26=$L$7,"Sprint 3 ("&TEXT(A26,"m/d")&")",IF(A26=$L$8,"Sprint 4 ("&TEXT(A26,"m/d")&")",IF(A26=$L$9,"Sprint 5 ("&TEXT(A26,"m/d")&")",IF(A26=$L$10,"Sprint 6 ("&TEXT(A26,"m/d")&")",IF(A26=$M$10,"Sprint 6 end ("&TEXT(A26,"m/d")&")",IF(D26>0,TEXT(A26,"m/d")," ")))))))) -> Sprint 1 (9/9) | C26: =MAX(0,$L$13-SUMIFS('Product Backlog'!$I$5:$I$504,'Product Backlog'!$G$5:$G$504,"<="&A26,'Product Backlog'!$G$5:$G$504,">0",'Product Backlog'!$I$5:$I$504,">0")) -> 1000 | D26: =SUMIFS('Product Backlog'!$I$5:$I$504,'Product Backlog'!$G$5:$G$504,A26,'Product Backlog'!$G$5:$G$504,">0",'Product Backlog'!$I$5:$I$504,">0") -> 0 | E26: =MAX(0,MIN($L$13,$L$13*($M$10-A26)/($M$10-$L$5))) -> 1000 | P26: =B26 -> Sprint 1 (9/9) | Q26: =C26 -> 1000 | R26: =E26 -> 1000
A27: =$L$5+1 -> 46275 | B27: =IF(A27=$L$5,"Sprint 1 ("&TEXT(A27,"m/d")&")",IF(A27=$L$6,"Sprint 2 ("&TEXT(A27,"m/d")&")",IF(A27=$L$7,"Sprint 3 ("&TEXT(A27,"m/d")&")",IF(A27=$L$8,"Sprint 4 ("&TEXT(A27,"m/d")&")",IF(A27=$L$9,"Sprint 5 ("&TEXT(A27,"m/d")&")",IF(A27=$L$10,"Sprint 6 ("&TEXT(A27,"m/d")&")",IF(A27=$M$10,"Sprint 6 end ("&TEXT(A27,"m/d")&")",IF(D27>0,TEXT(A27,"m/d")," ")))))))) | C27: =MAX(0,$L$13-SUMIFS('Product Backlog'!$I$5:$I$504,'Product Backlog'!$G$5:$G$504,"<="&A27,'Product Backlog'!$G$5:$G$504,">0",'Product Backlog'!$I$5:$I$504,">0")) -> 1000 | D27: =SUMIFS('Product Backlog'!$I$5:$I$504,'Product Backlog'!$G$5:$G$504,A27,'Product Backlog'!$G$5:$G$504,">0",'Product Backlog'!$I$5:$I$504,">0") -> 0 | E27: =MAX(0,MIN($L$13,$L$13*($M$10-A27)/($M$10-$L$5))) -> 988.09524 | P27: =B27 | Q27: =C27 -> 1000 | R27: =E27 -> 988.09524
A28: =$L$5+2 -> 46276 | B28: =IF(A28=$L$5,"Sprint 1 ("&TEXT(A28,"m/d")&")",IF(A28=$L$6,"Sprint 2 ("&TEXT(A28,"m/d")&")",IF(A28=$L$7,"Sprint 3 ("&TEXT(A28,"m/d")&")",IF(A28=$L$8,"Sprint 4 ("&TEXT(A28,"m/d")&")",IF(A28=$L$9,"Sprint 5 ("&TEXT(A28,"m/d")&")",IF(A28=$L$10,"Sprint 6 ("&TEXT(A28,"m/d")&")",IF(A28=$M$10,"Sprint 6 end ("&TEXT(A28,"m/d")&")",IF(D28>0,TEXT(A28,"m/d")," ")))))))) -> 9/11 | C28: =MAX(0,$L$13-SUMIFS('Product Backlog'!$I$5:$I$504,'Product Backlog'!$G$5:$G$504,"<="&A28,'Product Backlog'!$G$5:$G$504,">0",'Product Backlog'!$I$5:$I$504,">0")) -> 975 | D28: =SUMIFS('Product Backlog'!$I$5:$I$504,'Product Backlog'!$G$5:$G$504,A28,'Product Backlog'!$G$5:$G$504,">0",'Product Backlog'!$I$5:$I$504,">0") -> 25 | E28: =MAX(0,MIN($L$13,$L$13*($M$10-A28)/($M$10-$L$5))) -> 976.19048 | P28: =B28 -> 9/11 | Q28: =C28 -> 975 | R28: =E28 -> 976.19048
A29: =$L$5+3 -> 46277 | B29: =IF(A29=$L$5,"Sprint 1 ("&TEXT(A29,"m/d")&")",IF(A29=$L$6,"Sprint 2 ("&TEXT(A29,"m/d")&")",IF(A29=$L$7,"Sprint 3 ("&TEXT(A29,"m/d")&")",IF(A29=$L$8,"Sprint 4 ("&TEXT(A29,"m/d")&")",IF(A29=$L$9,"Sprint 5 ("&TEXT(A29,"m/d")&")",IF(A29=$L$10,"Sprint 6 ("&TEXT(A29,"m/d")&")",IF(A29=$M$10,"Sprint 6 end ("&TEXT(A29,"m/d")&")",IF(D29>0,TEXT(A29,"m/d")," ")))))))) | C29: =MAX(0,$L$13-SUMIFS('Product Backlog'!$I$5:$I$504,'Product Backlog'!$G$5:$G$504,"<="&A29,'Product Backlog'!$G$5:$G$504,">0",'Product Backlog'!$I$5:$I$504,">0")) -> 975 | D29: =SUMIFS('Product Backlog'!$I$5:$I$504,'Product Backlog'!$G$5:$G$504,A29,'Product Backlog'!$G$5:$G$504,">0",'Product Backlog'!$I$5:$I$504,">0") -> 0 | E29: =MAX(0,MIN($L$13,$L$13*($M$10-A29)/($M$10-$L$5))) -> 964.28571 | P29: =B29 | Q29: =C29 -> 975 | R29: =E29 -> 964.28571
A30: =$L$5+4 -> 46278 | B30: =IF(A30=$L$5,"Sprint 1 ("&TEXT(A30,"m/d")&")",IF(A30=$L$6,"Sprint 2 ("&TEXT(A30,"m/d")&")",IF(A30=$L$7,"Sprint 3 ("&TEXT(A30,"m/d")&")",IF(A30=$L$8,"Sprint 4 ("&TEXT(A30,"m/d")&")",IF(A30=$L$9,"Sprint 5 ("&TEXT(A30,"m/d")&")",IF(A30=$L$10,"Sprint 6 ("&TEXT(A30,"m/d")&")",IF(A30=$M$10,"Sprint 6 end ("&TEXT(A30,"m/d")&")",IF(D30>0,TEXT(A30,"m/d")," ")))))))) | C30: =MAX(0,$L$13-SUMIFS('Product Backlog'!$I$5:$I$504,'Product Backlog'!$G$5:$G$504,"<="&A30,'Product Backlog'!$G$5:$G$504,">0",'Product Backlog'!$I$5:$I$504,">0")) -> 975 | D30: =SUMIFS('Product Backlog'!$I$5:$I$504,'Product Backlog'!$G$5:$G$504,A30,'Product Backlog'!$G$5:$G$504,">0",'Product Backlog'!$I$5:$I$504,">0") -> 0 | E30: =MAX(0,MIN($L$13,$L$13*($M$10-A30)/($M$10-$L$5))) -> 952.38095 | P30: =B30 | Q30: =C30 -> 975 | R30: =E30 -> 952.38095
A31: =$L$5+5 -> 46279 | B31: =IF(A31=$L$5,"Sprint 1 ("&TEXT(A31,"m/d")&")",IF(A31=$L$6,"Sprint 2 ("&TEXT(A31,"m/d")&")",IF(A31=$L$7,"Sprint 3 ("&TEXT(A31,"m/d")&")",IF(A31=$L$8,"Sprint 4 ("&TEXT(A31,"m/d")&")",IF(A31=$L$9,"Sprint 5 ("&TEXT(A31,"m/d")&")",IF(A31=$L$10,"Sprint 6 ("&TEXT(A31,"m/d")&")",IF(A31=$M$10,"Sprint 6 end ("&TEXT(A31,"m/d")&")",IF(D31>0,TEXT(A31,"m/d")," ")))))))) | C31: =MAX(0,$L$13-SUMIFS('Product Backlog'!$I$5:$I$504,'Product Backlog'!$G$5:$G$504,"<="&A31,'Product Backlog'!$G$5:$G$504,">0",'Product Backlog'!$I$5:$I$504,">0")) -> 975 | D31: =SUMIFS('Product Backlog'!$I$5:$I$504,'Product Backlog'!$G$5:$G$504,A31,'Product Backlog'!$G$5:$G$504,">0",'Product Backlog'!$I$5:$I$504,">0") -> 0 | E31: =MAX(0,MIN($L$13,$L$13*($M$10-A31)/($M$10-$L$5))) -> 940.47619 | P31: =B31 | Q31: =C31 -> 975 | R31: =E31 -> 940.47619
A32: =$L$5+6 -> 46280 | B32: =IF(A32=$L$5,"Sprint 1 ("&TEXT(A32,"m/d")&")",IF(A32=$L$6,"Sprint 2 ("&TEXT(A32,"m/d")&")",IF(A32=$L$7,"Sprint 3 ("&TEXT(A32,"m/d")&")",IF(A32=$L$8,"Sprint 4 ("&TEXT(A32,"m/d")&")",IF(A32=$L$9,"Sprint 5 ("&TEXT(A32,"m/d")&")",IF(A32=$L$10,"Sprint 6 ("&TEXT(A32,"m/d")&")",IF(A32=$M$10,"Sprint 6 end ("&TEXT(A32,"m/d")&")",IF(D32>0,TEXT(A32,"m/d")," ")))))))) | C32: =MAX(0,$L$13-SUMIFS('Product Backlog'!$I$5:$I$504,'Product Backlog'!$G$5:$G$504,"<="&A32,'Product Backlog'!$G$5:$G$504,">0",'Product Backlog'!$I$5:$I$504,">0")) -> 975 | D32: =SUMIFS('Product Backlog'!$I$5:$I$504,'Product Backlog'!$G$5:$G$504,A32,'Product Backlog'!$G$5:$G$504,">0",'Product Backlog'!$I$5:$I$504,">0") -> 0 | E32: =MAX(0,MIN($L$13,$L$13*($M$10-A32)/($M$10-$L$5))) -> 928.57143 | P32: =B32 | Q32: =C32 -> 975 | R32: =E32 -> 928.57143
A33: =$L$5+7 -> 46281 | B33: =IF(A33=$L$5,"Sprint 1 ("&TEXT(A33,"m/d")&")",IF(A33=$L$6,"Sprint 2 ("&TEXT(A33,"m/d")&")",IF(A33=$L$7,"Sprint 3 ("&TEXT(A33,"m/d")&")",IF(A33=$L$8,"Sprint 4 ("&TEXT(A33,"m/d")&")",IF(A33=$L$9,"Sprint 5 ("&TEXT(A33,"m/d")&")",IF(A33=$L$10,"Sprint 6 ("&TEXT(A33,"m/d")&")",IF(A33=$M$10,"Sprint 6 end ("&TEXT(A33,"m/d")&")",IF(D33>0,TEXT(A33,"m/d")," ")))))))) -> 9/16 | C33: =MAX(0,$L$13-SUMIFS('Product Backlog'!$I$5:$I$504,'Product Backlog'!$G$5:$G$504,"<="&A33,'Product Backlog'!$G$5:$G$504,">0",'Product Backlog'!$I$5:$I$504,">0")) -> 920 | D33: =SUMIFS('Product Backlog'!$I$5:$I$504,'Product Backlog'!$G$5:$G$504,A33,'Product Backlog'!$G$5:$G$504,">0",'Product Backlog'!$I$5:$I$504,">0") -> 55 | E33: =MAX(0,MIN($L$13,$L$13*($M$10-A33)/($M$10-$L$5))) -> 916.66667 | P33: =B33 -> 9/16 | Q33: =C33 -> 920 | R33: =E33 -> 916.66667
A34: =$L$5+8 -> 46282 | B34: =IF(A34=$L$5,"Sprint 1 ("&TEXT(A34,"m/d")&")",IF(A34=$L$6,"Sprint 2 ("&TEXT(A34,"m/d")&")",IF(A34=$L$7,"Sprint 3 ("&TEXT(A34,"m/d")&")",IF(A34=$L$8,"Sprint 4 ("&TEXT(A34,"m/d")&")",IF(A34=$L$9,"Sprint 5 ("&TEXT(A34,"m/d")&")",IF(A34=$L$10,"Sprint 6 ("&TEXT(A34,"m/d")&")",IF(A34=$M$10,"Sprint 6 end ("&TEXT(A34,"m/d")&")",IF(D34>0,TEXT(A34,"m/d")," ")))))))) | C34: =MAX(0,$L$13-SUMIFS('Product Backlog'!$I$5:$I$504,'Product Backlog'!$G$5:$G$504,"<="&A34,'Product Backlog'!$G$5:$G$504,">0",'Product Backlog'!$I$5:$I$504,">0")) -> 920 | D34: =SUMIFS('Product Backlog'!$I$5:$I$504,'Product Backlog'!$G$5:$G$504,A34,'Product Backlog'!$G$5:$G$504,">0",'Product Backlog'!$I$5:$I$504,">0") -> 0 | E34: =MAX(0,MIN($L$13,$L$13*($M$10-A34)/($M$10-$L$5))) -> 904.7619 | P34: =B34 | Q34: =C34 -> 920 | R34: =E34 -> 904.7619
A35: =$L$5+9 -> 46283 | B35: =IF(A35=$L$5,"Sprint 1 ("&TEXT(A35,"m/d")&")",IF(A35=$L$6,"Sprint 2 ("&TEXT(A35,"m/d")&")",IF(A35=$L$7,"Sprint 3 ("&TEXT(A35,"m/d")&")",IF(A35=$L$8,"Sprint 4 ("&TEXT(A35,"m/d")&")",IF(A35=$L$9,"Sprint 5 ("&TEXT(A35,"m/d")&")",IF(A35=$L$10,"Sprint 6 ("&TEXT(A35,"m/d")&")",IF(A35=$M$10,"Sprint 6 end ("&TEXT(A35,"m/d")&")",IF(D35>0,TEXT(A35,"m/d")," ")))))))) -> 9/18 | C35: =MAX(0,$L$13-SUMIFS('Product Backlog'!$I$5:$I$504,'Product Backlog'!$G$5:$G$504,"<="&A35,'Product Backlog'!$G$5:$G$504,">0",'Product Backlog'!$I$5:$I$504,">0")) -> 905 | D35: =SUMIFS('Product Backlog'!$I$5:$I$504,'Product Backlog'!$G$5:$G$504,A35,'Product Backlog'!$G$5:$G$504,">0",'Product Backlog'!$I$5:$I$504,">0") -> 15 | E35: =MAX(0,MIN($L$13,$L$13*($M$10-A35)/($M$10-$L$5))) -> 892.85714 | P35: =B35 -> 9/18 | Q35: =C35 -> 905 | R35: =E35 -> 892.85714
A36: =$L$5+10 -> 46284 | B36: =IF(A36=$L$5,"Sprint 1 ("&TEXT(A36,"m/d")&")",IF(A36=$L$6,"Sprint 2 ("&TEXT(A36,"m/d")&")",IF(A36=$L$7,"Sprint 3 ("&TEXT(A36,"m/d")&")",IF(A36=$L$8,"Sprint 4 ("&TEXT(A36,"m/d")&")",IF(A36=$L$9,"Sprint 5 ("&TEXT(A36,"m/d")&")",IF(A36=$L$10,"Sprint 6 ("&TEXT(A36,"m/d")&")",IF(A36=$M$10,"Sprint 6 end ("&TEXT(A36,"m/d")&")",IF(D36>0,TEXT(A36,"m/d")," ")))))))) | C36: =MAX(0,$L$13-SUMIFS('Product Backlog'!$I$5:$I$504,'Product Backlog'!$G$5:$G$504,"<="&A36,'Product Backlog'!$G$5:$G$504,">0",'Product Backlog'!$I$5:$I$504,">0")) -> 905 | D36: =SUMIFS('Product Backlog'!$I$5:$I$504,'Product Backlog'!$G$5:$G$504,A36,'Product Backlog'!$G$5:$G$504,">0",'Product Backlog'!$I$5:$I$504,">0") -> 0 | E36: =MAX(0,MIN($L$13,$L$13*($M$10-A36)/($M$10-$L$5))) -> 880.95238 | P36: =B36 | Q36: =C36 -> 905 | R36: =E36 -> 880.95238
A37: =$L$5+11 -> 46285 | B37: =IF(A37=$L$5,"Sprint 1 ("&TEXT(A37,"m/d")&")",IF(A37=$L$6,"Sprint 2 ("&TEXT(A37,"m/d")&")",IF(A37=$L$7,"Sprint 3 ("&TEXT(A37,"m/d")&")",IF(A37=$L$8,"Sprint 4 ("&TEXT(A37,"m/d")&")",IF(A37=$L$9,"Sprint 5 ("&TEXT(A37,"m/d")&")",IF(A37=$L$10,"Sprint 6 ("&TEXT(A37,"m/d")&")",IF(A37=$M$10,"Sprint 6 end ("&TEXT(A37,"m/d")&")",IF(D37>0,TEXT(A37,"m/d")," ")))))))) | C37: =MAX(0,$L$13-SUMIFS('Product Backlog'!$I$5:$I$504,'Product Backlog'!$G$5:$G$504,"<="&A37,'Product Backlog'!$G$5:$G$504,">0",'Product Backlog'!$I$5:$I$504,">0")) -> 905 | D37: =SUMIFS('Product Backlog'!$I$5:$I$504,'Product Backlog'!$G$5:$G$504,A37,'Product Backlog'!$G$5:$G$504,">0",'Product Backlog'!$I$5:$I$504,">0") -> 0 | E37: =MAX(0,MIN($L$13,$L$13*($M$10-A37)/($M$10-$L$5))) -> 869.04762 | P37: =B37 | Q37: =C37 -> 905 | R37: =E37 -> 869.04762
A38: =$L$5+12 -> 46286 | B38: =IF(A38=$L$5,"Sprint 1 ("&TEXT(A38,"m/d")&")",IF(A38=$L$6,"Sprint 2 ("&TEXT(A38,"m/d")&")",IF(A38=$L$7,"Sprint 3 ("&TEXT(A38,"m/d")&")",IF(A38=$L$8,"Sprint 4 ("&TEXT(A38,"m/d")&")",IF(A38=$L$9,"Sprint 5 ("&TEXT(A38,"m/d")&")",IF(A38=$L$10,"Sprint 6 ("&TEXT(A38,"m/d")&")",IF(A38=$M$10,"Sprint 6 end ("&TEXT(A38,"m/d")&")",IF(D38>0,TEXT(A38,"m/d")," ")))))))) | C38: =MAX(0,$L$13-SUMIFS('Product Backlog'!$I$5:$I$504,'Product Backlog'!$G$5:$G$504,"<="&A38,'Product Backlog'!$G$5:$G$504,">0",'Product Backlog'!$I$5:$I$504,">0")) -> 905 | D38: =SUMIFS('Product Backlog'!$I$5:$I$504,'Product Backlog'!$G$5:$G$504,A38,'Product Backlog'!$G$5:$G$504,">0",'Product Backlog'!$I$5:$I$504,">0") -> 0 | E38: =MAX(0,MIN($L$13,$L$13*($M$10-A38)/($M$10-$L$5))) -> 857.14286 | P38: =B38 | Q38: =C38 -> 905 | R38: =E38 -> 857.14286
A39: =$L$5+13 -> 46287 | B39: =IF(A39=$L$5,"Sprint 1 ("&TEXT(A39,"m/d")&")",IF(A39=$L$6,"Sprint 2 ("&TEXT(A39,"m/d")&")",IF(A39=$L$7,"Sprint 3 ("&TEXT(A39,"m/d")&")",IF(A39=$L$8,"Sprint 4 ("&TEXT(A39,"m/d")&")",IF(A39=$L$9,"Sprint 5 ("&TEXT(A39,"m/d")&")",IF(A39=$L$10,"Sprint 6 ("&TEXT(A39,"m/d")&")",IF(A39=$M$10,"Sprint 6 end ("&TEXT(A39,"m/d")&")",IF(D39>0,TEXT(A39,"m/d")," ")))))))) | C39: =MAX(0,$L$13-SUMIFS('Product Backlog'!$I$5:$I$504,'Product Backlog'!$G$5:$G$504,"<="&A39,'Product Backlog'!$G$5:$G$504,">0",'Product Backlog'!$I$5:$I$504,">0")) -> 905 | D39: =SUMIFS('Product Backlog'!$I$5:$I$504,'Product Backlog'!$G$5:$G$504,A39,'Product Backlog'!$G$5:$G$504,">0",'Product Backlog'!$I$5:$I$504,">0") -> 0 | E39: =MAX(0,MIN($L$13,$L$13*($M$10-A39)/($M$10-$L$5))) -> 845.2381 | P39: =B39 | Q39: =C39 -> 905 | R39: =E39 -> 845.2381
A40: =$L$5+14 -> 46288 | B40: =IF(A40=$L$5,"Sprint 1 ("&TEXT(A40,"m/d")&")",IF(A40=$L$6,"Sprint 2 ("&TEXT(A40,"m/d")&")",IF(A40=$L$7,"Sprint 3 ("&TEXT(A40,"m/d")&")",IF(A40=$L$8,"Sprint 4 ("&TEXT(A40,"m/d")&")",IF(A40=$L$9,"Sprint 5 ("&TEXT(A40,"m/d")&")",IF(A40=$L$10,"Sprint 6 ("&TEXT(A40,"m/d")&")",IF(A40=$M$10,"Sprint 6 end ("&TEXT(A40,"m/d")&")",IF(D40>0,TEXT(A40,"m/d")," ")))))))) -> Sprint 2 (9/23) | C40: =MAX(0,$L$13-SUMIFS('Product Backlog'!$I$5:$I$504,'Product Backlog'!$G$5:$G$504,"<="&A40,'Product Backlog'!$G$5:$G$504,">0",'Product Backlog'!$I$5:$I$504,">0")) -> 860 | D40: =SUMIFS('Product Backlog'!$I$5:$I$504,'Product Backlog'!$G$5:$G$504,A40,'Product Backlog'!$G$5:$G$504,">0",'Product Backlog'!$I$5:$I$504,">0") -> 45 | E40: =MAX(0,MIN($L$13,$L$13*($M$10-A40)/($M$10-$L$5))) -> 833.33333 | P40: =B40 -> Sprint 2 (9/23) | Q40: =C40 -> 860 | R40: =E40 -> 833.33333
A41: =$L$5+15 -> 46289 | B41: =IF(A41=$L$5,"Sprint 1 ("&TEXT(A41,"m/d")&")",IF(A41=$L$6,"Sprint 2 ("&TEXT(A41,"m/d")&")",IF(A41=$L$7,"Sprint 3 ("&TEXT(A41,"m/d")&")",IF(A41=$L$8,"Sprint 4 ("&TEXT(A41,"m/d")&")",IF(A41=$L$9,"Sprint 5 ("&TEXT(A41,"m/d")&")",IF(A41=$L$10,"Sprint 6 ("&TEXT(A41,"m/d")&")",IF(A41=$M$10,"Sprint 6 end ("&TEXT(A41,"m/d")&")",IF(D41>0,TEXT(A41,"m/d")," ")))))))) | C41: =MAX(0,$L$13-SUMIFS('Product Backlog'!$I$5:$I$504,'Product Backlog'!$G$5:$G$504,"<="&A41,'Product Backlog'!$G$5:$G$504,">0",'Product Backlog'!$I$5:$I$504,">0")) -> 860 | D41: =SUMIFS('Product Backlog'!$I$5:$I$504,'Product Backlog'!$G$5:$G$504,A41,'Product Backlog'!$G$5:$G$504,">0",'Product Backlog'!$I$5:$I$504,">0") -> 0 | E41: =MAX(0,MIN($L$13,$L$13*($M$10-A41)/($M$10-$L$5))) -> 821.42857 | P41: =B41 | Q41: =C41 -> 860 | R41: =E41 -> 821.42857
A42: =$L$5+16 -> 46290 | B42: =IF(A42=$L$5,"Sprint 1 ("&TEXT(A42,"m/d")&")",IF(A42=$L$6,"Sprint 2 ("&TEXT(A42,"m/d")&")",IF(A42=$L$7,"Sprint 3 ("&TEXT(A42,"m/d")&")",IF(A42=$L$8,"Sprint 4 ("&TEXT(A42,"m/d")&")",IF(A42=$L$9,"Sprint 5 ("&TEXT(A42,"m/d")&")",IF(A42=$L$10,"Sprint 6 ("&TEXT(A42,"m/d")&")",IF(A42=$M$10,"Sprint 6 end ("&TEXT(A42,"m/d")&")",IF(D42>0,TEXT(A42,"m/d")," ")))))))) | C42: =MAX(0,$L$13-SUMIFS('Product Backlog'!$I$5:$I$504,'Product Backlog'!$G$5:$G$504,"<="&A42,'Product Backlog'!$G$5:$G$504,">0",'Product Backlog'!$I$5:$I$504,">0")) -> 860 | D42: =SUMIFS('Product Backlog'!$I$5:$I$504,'Product Backlog'!$G$5:$G$504,A42,'Product Backlog'!$G$5:$G$504,">0",'Product Backlog'!$I$5:$I$504,">0") -> 0 | E42: =MAX(0,MIN($L$13,$L$13*($M$10-A42)/($M$10-$L$5))) -> 809.52381 | P42: =B42 | Q42: =C42 -> 860 | R42: =E42 -> 809.52381
A43: =$L$5+17 -> 46291 | B43: =IF(A43=$L$5,"Sprint 1 ("&TEXT(A43,"m/d")&")",IF(A43=$L$6,"Sprint 2 ("&TEXT(A43,"m/d")&")",IF(A43=$L$7,"Sprint 3 ("&TEXT(A43,"m/d")&")",IF(A43=$L$8,"Sprint 4 ("&TEXT(A43,"m/d")&")",IF(A43=$L$9,"Sprint 5 ("&TEXT(A43,"m/d")&")",IF(A43=$L$10,"Sprint 6 ("&TEXT(A43,"m/d")&")",IF(A43=$M$10,"Sprint 6 end ("&TEXT(A43,"m/d")&")",IF(D43>0,TEXT(A43,"m/d")," ")))))))) | C43: =MAX(0,$L$13-SUMIFS('Product Backlog'!$I$5:$I$504,'Product Backlog'!$G$5:$G$504,"<="&A43,'Product Backlog'!$G$5:$G$504,">0",'Product Backlog'!$I$5:$I$504,">0")) -> 860 | D43: =SUMIFS('Product Backlog'!$I$5:$I$504,'Product Backlog'!$G$5:$G$504,A43,'Product Backlog'!$G$5:$G$504,">0",'Product Backlog'!$I$5:$I$504,">0") -> 0 | E43: =MAX(0,MIN($L$13,$L$13*($M$10-A43)/($M$10-$L$5))) -> 797.61905 | P43: =B43 | Q43: =C43 -> 860 | R43: =E43 -> 797.61905
A44: =$L$5+18 -> 46292 | B44: =IF(A44=$L$5,"Sprint 1 ("&TEXT(A44,"m/d")&")",IF(A44=$L$6,"Sprint 2 ("&TEXT(A44,"m/d")&")",IF(A44=$L$7,"Sprint 3 ("&TEXT(A44,"m/d")&")",IF(A44=$L$8,"Sprint 4 ("&TEXT(A44,"m/d")&")",IF(A44=$L$9,"Sprint 5 ("&TEXT(A44,"m/d")&")",IF(A44=$L$10,"Sprint 6 ("&TEXT(A44,"m/d")&")",IF(A44=$M$10,"Sprint 6 end ("&TEXT(A44,"m/d")&")",IF(D44>0,TEXT(A44,"m/d")," ")))))))) | C44: =MAX(0,$L$13-SUMIFS('Product Backlog'!$I$5:$I$504,'Product Backlog'!$G$5:$G$504,"<="&A44,'Product Backlog'!$G$5:$G$504,">0",'Product Backlog'!$I$5:$I$504,">0")) -> 860 | D44: =SUMIFS('Product Backlog'!$I$5:$I$504,'Product Backlog'!$G$5:$G$504,A44,'Product Backlog'!$G$5:$G$504,">0",'Product Backlog'!$I$5:$I$504,">0") -> 0 | E44: =MAX(0,MIN($L$13,$L$13*($M$10-A44)/($M$10-$L$5))) -> 785.71429 | P44: =B44 | Q44: =C44 -> 860 | R44: =E44 -> 785.71429
A45: =$L$5+19 -> 46293 | B45: =IF(A45=$L$5,"Sprint 1 ("&TEXT(A45,"m/d")&")",IF(A45=$L$6,"Sprint 2 ("&TEXT(A45,"m/d")&")",IF(A45=$L$7,"Sprint 3 ("&TEXT(A45,"m/d")&")",IF(A45=$L$8,"Sprint 4 ("&TEXT(A45,"m/d")&")",IF(A45=$L$9,"Sprint 5 ("&TEXT(A45,"m/d")&")",IF(A45=$L$10,"Sprint 6 ("&TEXT(A45,"m/d")&")",IF(A45=$M$10,"Sprint 6 end ("&TEXT(A45,"m/d")&")",IF(D45>0,TEXT(A45,"m/d")," ")))))))) -> 9/28 | C45: =MAX(0,$L$13-SUMIFS('Product Backlog'!$I$5:$I$504,'Product Backlog'!$G$5:$G$504,"<="&A45,'Product Backlog'!$G$5:$G$504,">0",'Product Backlog'!$I$5:$I$504,">0")) -> 815 | D45: =SUMIFS('Product Backlog'!$I$5:$I$504,'Product Backlog'!$G$5:$G$504,A45,'Product Backlog'!$G$5:$G$504,">0",'Product Backlog'!$I$5:$I$504,">0") -> 45 | E45: =MAX(0,MIN($L$13,$L$13*($M$10-A45)/($M$10-$L$5))) -> 773.80952 | P45: =B45 -> 9/28 | Q45: =C45 -> 815 | R45: =E45 -> 773.80952
A46: =$L$5+20 -> 46294 | B46: =IF(A46=$L$5,"Sprint 1 ("&TEXT(A46,"m/d")&")",IF(A46=$L$6,"Sprint 2 ("&TEXT(A46,"m/d")&")",IF(A46=$L$7,"Sprint 3 ("&TEXT(A46,"m/d")&")",IF(A46=$L$8,"Sprint 4 ("&TEXT(A46,"m/d")&")",IF(A46=$L$9,"Sprint 5 ("&TEXT(A46,"m/d")&")",IF(A46=$L$10,"Sprint 6 ("&TEXT(A46,"m/d")&")",IF(A46=$M$10,"Sprint 6 end ("&TEXT(A46,"m/d")&")",IF(D46>0,TEXT(A46,"m/d")," ")))))))) | C46: =MAX(0,$L$13-SUMIFS('Product Backlog'!$I$5:$I$504,'Product Backlog'!$G$5:$G$504,"<="&A46,'Product Backlog'!$G$5:$G$504,">0",'Product Backlog'!$I$5:$I$504,">0")) -> 815 | D46: =SUMIFS('Product Backlog'!$I$5:$I$504,'Product Backlog'!$G$5:$G$504,A46,'Product Backlog'!$G$5:$G$504,">0",'Product Backlog'!$I$5:$I$504,">0") -> 0 | E46: =MAX(0,MIN($L$13,$L$13*($M$10-A46)/($M$10-$L$5))) -> 761.90476 | P46: =B46 | Q46: =C46 -> 815 | R46: =E46 -> 761.90476
A47: =$L$5+21 -> 46295 | B47: =IF(A47=$L$5,"Sprint 1 ("&TEXT(A47,"m/d")&")",IF(A47=$L$6,"Sprint 2 ("&TEXT(A47,"m/d")&")",IF(A47=$L$7,"Sprint 3 ("&TEXT(A47,"m/d")&")",IF(A47=$L$8,"Sprint 4 ("&TEXT(A47,"m/d")&")",IF(A47=$L$9,"Sprint 5 ("&TEXT(A47,"m/d")&")",IF(A47=$L$10,"Sprint 6 ("&TEXT(A47,"m/d")&")",IF(A47=$M$10,"Sprint 6 end ("&TEXT(A47,"m/d")&")",IF(D47>0,TEXT(A47,"m/d")," ")))))))) -> 9/30 | C47: =MAX(0,$L$13-SUMIFS('Product Backlog'!$I$5:$I$504,'Product Backlog'!$G$5:$G$504,"<="&A47,'Product Backlog'!$G$5:$G$504,">0",'Product Backlog'!$I$5:$I$504,">0")) -> 765 | D47: =SUMIFS('Product Backlog'!$I$5:$I$504,'Product Backlog'!$G$5:$G$504,A47,'Product Backlog'!$G$5:$G$504,">0",'Product Backlog'!$I$5:$I$504,">0") -> 50 | E47: =MAX(0,MIN($L$13,$L$13*($M$10-A47)/($M$10-$L$5))) -> 750 | P47: =B47 -> 9/30 | Q47: =C47 -> 765 | R47: =E47 -> 750
A48: =$L$5+22 -> 46296 | B48: =IF(A48=$L$5,"Sprint 1 ("&TEXT(A48,"m/d")&")",IF(A48=$L$6,"Sprint 2 ("&TEXT(A48,"m/d")&")",IF(A48=$L$7,"Sprint 3 ("&TEXT(A48,"m/d")&")",IF(A48=$L$8,"Sprint 4 ("&TEXT(A48,"m/d")&")",IF(A48=$L$9,"Sprint 5 ("&TEXT(A48,"m/d")&")",IF(A48=$L$10,"Sprint 6 ("&TEXT(A48,"m/d")&")",IF(A48=$M$10,"Sprint 6 end ("&TEXT(A48,"m/d")&")",IF(D48>0,TEXT(A48,"m/d")," ")))))))) | C48: =MAX(0,$L$13-SUMIFS('Product Backlog'!$I$5:$I$504,'Product Backlog'!$G$5:$G$504,"<="&A48,'Product Backlog'!$G$5:$G$504,">0",'Product Backlog'!$I$5:$I$504,">0")) -> 765 | D48: =SUMIFS('Product Backlog'!$I$5:$I$504,'Product Backlog'!$G$5:$G$504,A48,'Product Backlog'!$G$5:$G$504,">0",'Product Backlog'!$I$5:$I$504,">0") -> 0 | E48: =MAX(0,MIN($L$13,$L$13*($M$10-A48)/($M$10-$L$5))) -> 738.09524 | P48: =B48 | Q48: =C48 -> 765 | R48: =E48 -> 738.09524
A49: =$L$5+23 -> 46297 | B49: =IF(A49=$L$5,"Sprint 1 ("&TEXT(A49,"m/d")&")",IF(A49=$L$6,"Sprint 2 ("&TEXT(A49,"m/d")&")",IF(A49=$L$7,"Sprint 3 ("&TEXT(A49,"m/d")&")",IF(A49=$L$8,"Sprint 4 ("&TEXT(A49,"m/d")&")",IF(A49=$L$9,"Sprint 5 ("&TEXT(A49,"m/d")&")",IF(A49=$L$10,"Sprint 6 ("&TEXT(A49,"m/d")&")",IF(A49=$M$10,"Sprint 6 end ("&TEXT(A49,"m/d")&")",IF(D49>0,TEXT(A49,"m/d")," ")))))))) | C49: =MAX(0,$L$13-SUMIFS('Product Backlog'!$I$5:$I$504,'Product Backlog'!$G$5:$G$504,"<="&A49,'Product Backlog'!$G$5:$G$504,">0",'Product Backlog'!$I$5:$I$504,">0")) -> 765 | D49: =SUMIFS('Product Backlog'!$I$5:$I$504,'Product Backlog'!$G$5:$G$504,A49,'Product Backlog'!$G$5:$G$504,">0",'Product Backlog'!$I$5:$I$504,">0") -> 0 | E49: =MAX(0,MIN($L$13,$L$13*($M$10-A49)/($M$10-$L$5))) -> 726.19048 | P49: =B49 | Q49: =C49 -> 765 | R49: =E49 -> 726.19048
A50: =$L$5+24 -> 46298 | B50: =IF(A50=$L$5,"Sprint 1 ("&TEXT(A50,"m/d")&")",IF(A50=$L$6,"Sprint 2 ("&TEXT(A50,"m/d")&")",IF(A50=$L$7,"Sprint 3 ("&TEXT(A50,"m/d")&")",IF(A50=$L$8,"Sprint 4 ("&TEXT(A50,"m/d")&")",IF(A50=$L$9,"Sprint 5 ("&TEXT(A50,"m/d")&")",IF(A50=$L$10,"Sprint 6 ("&TEXT(A50,"m/d")&")",IF(A50=$M$10,"Sprint 6 end ("&TEXT(A50,"m/d")&")",IF(D50>0,TEXT(A50,"m/d")," ")))))))) | C50: =MAX(0,$L$13-SUMIFS('Product Backlog'!$I$5:$I$504,'Product Backlog'!$G$5:$G$504,"<="&A50,'Product Backlog'!$G$5:$G$504,">0",'Product Backlog'!$I$5:$I$504,">0")) -> 765 | D50: =SUMIFS('Product Backlog'!$I$5:$I$504,'Product Backlog'!$G$5:$G$504,A50,'Product Backlog'!$G$5:$G$504,">0",'Product Backlog'!$I$5:$I$504,">0") -> 0 | E50: =MAX(0,MIN($L$13,$L$13*($M$10-A50)/($M$10-$L$5))) -> 714.28571 | P50: =B50 | Q50: =C50 -> 765 | R50: =E50 -> 714.28571
...

Sheet Sprint 1
A1: Sprint 1
A2: Sprint 1 records and backlog view. Edit task details on the Product Backlog sheet; this view updates from the Sprint #.
A4: Sprint # | B4: 1 | D4: Start date | E4: 46274 | G4: End date | H4: 46283 | K4: Historical note: Sprint 1 records Task #4’s RSS demo as implemented on 9/16/2026. The Product Backlog keeps the remaining RSS work assigned to Sprint 2, so Task #4 is not duplicated in this sprint’s automatic backlog view.
A5: Sprint goal | B5: Create a basic webserver and WebUI to serve over domain (esof423.csit.help) Wire up RSS implementation Find client
A7: Tasks | B7: =COUNTIFS('Product Backlog'!$B$5:$B$504,1,'Product Backlog'!$C$5:$C$504,"<>") -> 3 | C7: Completed | D7: =COUNTIFS('Product Backlog'!$B$5:$B$504,1,'Product Backlog'!$D$5:$D$504,"Done")+COUNTIFS('Product Backlog'!$B$5:$B$504,1,'Product Backlog'!$D$5:$D$504,"Completed") -> 3 | E7: Hours logged | F7: =SUMIFS('Product Backlog'!$H$5:$H$504,'Product Backlog'!$B$5:$B$504,1) -> 3.5 | G7: Work points | H7: =SUMIFS('Product Backlog'!$I$5:$I$504,'Product Backlog'!$B$5:$B$504,1) -> 95
A8: Auto-generated view. Do not enter tasks here; add or change them on Product Backlog.
A9: Task # | B9: Sprint # | C9: Task description | D9: Status | E9: Maintainer | F9: Date added | G9: Date completed | H9: Hours to complete | I9: Work points assigned
A10: =IF($J10="","",IF(ISBLANK(INDEX('Product Backlog'!$A$5:$A$504,$J10)),"",INDEX('Product Backlog'!$A$5:$A$504,$J10))) -> 1 | B10: =IF($J10="","",IF(ISBLANK(INDEX('Product Backlog'!$B$5:$B$504,$J10)),"",INDEX('Product Backlog'!$B$5:$B$504,$J10))) -> 1 | C10: =IF($J10="","",IF(ISBLANK(INDEX('Product Backlog'!$C$5:$C$504,$J10)),"",INDEX('Product Backlog'!$C$5:$C$504,$J10))) -> Basic webpage and repo setup | D10: =IF($J10="","",IF(ISBLANK(INDEX('Product Backlog'!$D$5:$D$504,$J10)),"",INDEX('Product Backlog'!$D$5:$D$504,$J10))) -> Done | E10: =IF($J10="","",IF(ISBLANK(INDEX('Product Backlog'!$E$5:$E$504,$J10)),"",INDEX('Product Backlog'!$E$5:$E$504,$J10))) -> chropic | F10: =IF($J10="","",IF(ISBLANK(INDEX('Product Backlog'!$F$5:$F$504,$J10)),"",INDEX('Product Backlog'!$F$5:$F$504,$J10))) -> 46274 | G10: =IF($J10="","",IF(ISBLANK(INDEX('Product Backlog'!$G$5:$G$504,$J10)),"",INDEX('Product Backlog'!$G$5:$G$504,$J10))) -> 46276 | H10: =IF($J10="","",IF(ISBLANK(INDEX('Product Backlog'!$H$5:$H$504,$J10)),"",INDEX('Product Backlog'!$H$5:$H$504,$J10))) -> 0.5 | I10: =IF($J10="","",IF(ISBLANK(INDEX('Product Backlog'!$I$5:$I$504,$J10)),"",INDEX('Product Backlog'!$I$5:$I$504,$J10))) -> 25 | J10: =IFERROR(MATCH($B$4&"-"&ROWS($A$10:A10),'Product Backlog'!$J$5:$J$504,0),"") -> 1
A11: =IF($J11="","",IF(ISBLANK(INDEX('Product Backlog'!$A$5:$A$504,$J11)),"",INDEX('Product Backlog'!$A$5:$A$504,$J11))) -> 2 | B11: =IF($J11="","",IF(ISBLANK(INDEX('Product Backlog'!$B$5:$B$504,$J11)),"",INDEX('Product Backlog'!$B$5:$B$504,$J11))) -> 1 | C11: =IF($J11="","",IF(ISBLANK(INDEX('Product Backlog'!$C$5:$C$504,$J11)),"",INDEX('Product Backlog'!$C$5:$C$504,$J11))) -> Actual web interface and demo features | D11: =IF($J11="","",IF(ISBLANK(INDEX('Product Backlog'!$D$5:$D$504,$J11)),"",INDEX('Product Backlog'!$D$5:$D$504,$J11))) -> Done | E11: oogwaysprophecy732 | F11: =IF($J11="","",IF(ISBLANK(INDEX('Product Backlog'!$F$5:$F$504,$J11)),"",INDEX('Product Backlog'!$F$5:$F$504,$J11))) -> 46274 | G11: =IF($J11="","",IF(ISBLANK(INDEX('Product Backlog'!$G$5:$G$504,$J11)),"",INDEX('Product Backlog'!$G$5:$G$504,$J11))) -> 46281 | H11: =IF($J11="","",IF(ISBLANK(INDEX('Product Backlog'!$H$5:$H$504,$J11)),"",INDEX('Product Backlog'!$H$5:$H$504,$J11))) -> 2 | I11: =IF($J11="","",IF(ISBLANK(INDEX('Product Backlog'!$I$5:$I$504,$J11)),"",INDEX('Product Backlog'!$I$5:$I$504,$J11))) -> 55 | J11: =IFERROR(MATCH($B$4&"-"&ROWS($A$10:A11),'Product Backlog'!$J$5:$J$504,0),"") -> 2
A12: =IF($J12="","",IF(ISBLANK(INDEX('Product Backlog'!$A$5:$A$504,$J12)),"",INDEX('Product Backlog'!$A$5:$A$504,$J12))) -> 3 | B12: =IF($J12="","",IF(ISBLANK(INDEX('Product Backlog'!$B$5:$B$504,$J12)),"",INDEX('Product Backlog'!$B$5:$B$504,$J12))) -> 1 | C12: =IF($J12="","",IF(ISBLANK(INDEX('Product Backlog'!$C$5:$C$504,$J12)),"",INDEX('Product Backlog'!$C$5:$C$504,$J12))) -> Find client and update README | D12: =IF($J12="","",IF(ISBLANK(INDEX('Product Backlog'!$D$5:$D$504,$J12)),"",INDEX('Product Backlog'!$D$5:$D$504,$J12))) -> Done | E12: =IF($J12="","",IF(ISBLANK(INDEX('Product Backlog'!$E$5:$E$504,$J12)),"",INDEX('Product Backlog'!$E$5:$E$504,$J12))) -> chropic | F12: =IF($J12="","",IF(ISBLANK(INDEX('Product Backlog'!$F$5:$F$504,$J12)),"",INDEX('Product Backlog'!$F$5:$F$504,$J12))) -> 46274 | G12: =IF($J12="","",IF(ISBLANK(INDEX('Product Backlog'!$G$5:$G$504,$J12)),"",INDEX('Product Backlog'!$G$5:$G$504,$J12))) -> 46283 | H12: =IF($J12="","",IF(ISBLANK(INDEX('Product Backlog'!$H$5:$H$504,$J12)),"",INDEX('Product Backlog'!$H$5:$H$504,$J12))) -> 1 | I12: =IF($J12="","",IF(ISBLANK(INDEX('Product Backlog'!$I$5:$I$504,$J12)),"",INDEX('Product Backlog'!$I$5:$I$504,$J12))) -> 15 | J12: =IFERROR(MATCH($B$4&"-"&ROWS($A$10:A12),'Product Backlog'!$J$5:$J$504,0),"") -> 3
A13: =IF($J13="","",IF(ISBLANK(INDEX('Product Backlog'!$A$5:$A$504,$J13)),"",INDEX('Product Backlog'!$A$5:$A$504,$J13))) | B13: =IF($J13="","",IF(ISBLANK(INDEX('Product Backlog'!$B$5:$B$504,$J13)),"",INDEX('Product Backlog'!$B$5:$B$504,$J13))) | C13: =IF($J13="","",IF(ISBLANK(INDEX('Product Backlog'!$C$5:$C$504,$J13)),"",INDEX('Product Backlog'!$C$5:$C$504,$J13))) | D13: =IF($J13="","",IF(ISBLANK(INDEX('Product Backlog'!$D$5:$D$504,$J13)),"",INDEX('Product Backlog'!$D$5:$D$504,$J13))) | E13: =IF($J13="","",IF(ISBLANK(INDEX('Product Backlog'!$E$5:$E$504,$J13)),"",INDEX('Product Backlog'!$E$5:$E$504,$J13))) | F13: =IF($J13="","",IF(ISBLANK(INDEX('Product Backlog'!$F$5:$F$504,$J13)),"",INDEX('Product Backlog'!$F$5:$F$504,$J13))) | G13: =IF($J13="","",IF(ISBLANK(INDEX('Product Backlog'!$G$5:$G$504,$J13)),"",INDEX('Product Backlog'!$G$5:$G$504,$J13))) | H13: =IF($J13="","",IF(ISBLANK(INDEX('Product Backlog'!$H$5:$H$504,$J13)),"",INDEX('Product Backlog'!$H$5:$H$504,$J13))) | I13: =IF($J13="","",IF(ISBLANK(INDEX('Product Backlog'!$I$5:$I$504,$J13)),"",INDEX('Product Backlog'!$I$5:$I$504,$J13))) | J13: =IFERROR(MATCH($B$4&"-"&ROWS($A$10:A13),'Product Backlog'!$J$5:$J$504,0),"")
A14: =IF($J14="","",IF(ISBLANK(INDEX('Product Backlog'!$A$5:$A$504,$J14)),"",INDEX('Product Backlog'!$A$5:$A$504,$J14))) | B14: =IF($J14="","",IF(ISBLANK(INDEX('Product Backlog'!$B$5:$B$504,$J14)),"",INDEX('Product Backlog'!$B$5:$B$504,$J14))) | C14: =IF($J14="","",IF(ISBLANK(INDEX('Product Backlog'!$C$5:$C$504,$J14)),"",INDEX('Product Backlog'!$C$5:$C$504,$J14))) | D14: =IF($J14="","",IF(ISBLANK(INDEX('Product Backlog'!$D$5:$D$504,$J14)),"",INDEX('Product Backlog'!$D$5:$D$504,$J14))) | E14: =IF($J14="","",IF(ISBLANK(INDEX('Product Backlog'!$E$5:$E$504,$J14)),"",INDEX('Product Backlog'!$E$5:$E$504,$J14))) | F14: =IF($J14="","",IF(ISBLANK(INDEX('Product Backlog'!$F$5:$F$504,$J14)),"",INDEX('Product Backlog'!$F$5:$F$504,$J14))) | G14: =IF($J14="","",IF(ISBLANK(INDEX('Product Backlog'!$G$5:$G$504,$J14)),"",INDEX('Product Backlog'!$G$5:$G$504,$J14))) | H14: =IF($J14="","",IF(ISBLANK(INDEX('Product Backlog'!$H$5:$H$504,$J14)),"",INDEX('Product Backlog'!$H$5:$H$504,$J14))) | I14: =IF($J14="","",IF(ISBLANK(INDEX('Product Backlog'!$I$5:$I$504,$J14)),"",INDEX('Product Backlog'!$I$5:$I$504,$J14))) | J14: =IFERROR(MATCH($B$4&"-"&ROWS($A$10:A14),'Product Backlog'!$J$5:$J$504,0),"")
A15: =IF($J15="","",IF(ISBLANK(INDEX('Product Backlog'!$A$5:$A$504,$J15)),"",INDEX('Product Backlog'!$A$5:$A$504,$J15))) | B15: =IF($J15="","",IF(ISBLANK(INDEX('Product Backlog'!$B$5:$B$504,$J15)),"",INDEX('Product Backlog'!$B$5:$B$504,$J15))) | C15: =IF($J15="","",IF(ISBLANK(INDEX('Product Backlog'!$C$5:$C$504,$J15)),"",INDEX('Product Backlog'!$C$5:$C$504,$J15))) | D15: =IF($J15="","",IF(ISBLANK(INDEX('Product Backlog'!$D$5:$D$504,$J15)),"",INDEX('Product Backlog'!$D$5:$D$504,$J15))) | E15: =IF($J15="","",IF(ISBLANK(INDEX('Product Backlog'!$E$5:$E$504,$J15)),"",INDEX('Product Backlog'!$E$5:$E$504,$J15))) | F15: =IF($J15="","",IF(ISBLANK(INDEX('Product Backlog'!$F$5:$F$504,$J15)),"",INDEX('Product Backlog'!$F$5:$F$504,$J15))) | G15: =IF($J15="","",IF(ISBLANK(INDEX('Product Backlog'!$G$5:$G$504,$J15)),"",INDEX('Product Backlog'!$G$5:$G$504,$J15))) | H15: =IF($J15="","",IF(ISBLANK(INDEX('Product Backlog'!$H$5:$H$504,$J15)),"",INDEX('Product Backlog'!$H$5:$H$504,$J15))) | I15: =IF($J15="","",IF(ISBLANK(INDEX('Product Backlog'!$I$5:$I$504,$J15)),"",INDEX('Product Backlog'!$I$5:$I$504,$J15))) | J15: =IFERROR(MATCH($B$4&"-"&ROWS($A$10:A15),'Product Backlog'!$J$5:$J$504,0),"")
A16: =IF($J16="","",IF(ISBLANK(INDEX('Product Backlog'!$A$5:$A$504,$J16)),"",INDEX('Product Backlog'!$A$5:$A$504,$J16))) | B16: =IF($J16="","",IF(ISBLANK(INDEX('Product Backlog'!$B$5:$B$504,$J16)),"",INDEX('Product Backlog'!$B$5:$B$504,$J16))) | C16: =IF($J16="","",IF(ISBLANK(INDEX('Product Backlog'!$C$5:$C$504,$J16)),"",INDEX('Product Backlog'!$C$5:$C$504,$J16))) | D16: =IF($J16="","",IF(ISBLANK(INDEX('Product Backlog'!$D$5:$D$504,$J16)),"",INDEX('Product Backlog'!$D$5:$D$504,$J16))) | E16: =IF($J16="","",IF(ISBLANK(INDEX('Product Backlog'!$E$5:$E$504,$J16)),"",INDEX('Product Backlog'!$E$5:$E$504,$J16))) | F16: =IF($J16="","",IF(ISBLANK(INDEX('Product Backlog'!$F$5:$F$504,$J16)),"",INDEX('Product Backlog'!$F$5:$F$504,$J16))) | G16: =IF($J16="","",IF(ISBLANK(INDEX('Product Backlog'!$G$5:$G$504,$J16)),"",INDEX('Product Backlog'!$G$5:$G$504,$J16))) | H16: =IF($J16="","",IF(ISBLANK(INDEX('Product Backlog'!$H$5:$H$504,$J16)),"",INDEX('Product Backlog'!$H$5:$H$504,$J16))) | I16: =IF($J16="","",IF(ISBLANK(INDEX('Product Backlog'!$I$5:$I$504,$J16)),"",INDEX('Product Backlog'!$I$5:$I$504,$J16))) | J16: =IFERROR(MATCH($B$4&"-"&ROWS($A$10:A16),'Product Backlog'!$J$5:$J$504,0),"")
A17: =IF($J17="","",IF(ISBLANK(INDEX('Product Backlog'!$A$5:$A$504,$J17)),"",INDEX('Product Backlog'!$A$5:$A$504,$J17))) | B17: =IF($J17="","",IF(ISBLANK(INDEX('Product Backlog'!$B$5:$B$504,$J17)),"",INDEX('Product Backlog'!$B$5:$B$504,$J17))) | C17: =IF($J17="","",IF(ISBLANK(INDEX('Product Backlog'!$C$5:$C$504,$J17)),"",INDEX('Product Backlog'!$C$5:$C$504,$J17))) | D17: =IF($J17="","",IF(ISBLANK(INDEX('Product Backlog'!$D$5:$D$504,$J17)),"",INDEX('Product Backlog'!$D$5:$D$504,$J17))) | E17: =IF($J17="","",IF(ISBLANK(INDEX('Product Backlog'!$E$5:$E$504,$J17)),"",INDEX('Product Backlog'!$E$5:$E$504,$J17))) | F17: =IF($J17="","",IF(ISBLANK(INDEX('Product Backlog'!$F$5:$F$504,$J17)),"",INDEX('Product Backlog'!$F$5:$F$504,$J17))) | G17: =IF($J17="","",IF(ISBLANK(INDEX('Product Backlog'!$G$5:$G$504,$J17)),"",INDEX('Product Backlog'!$G$5:$G$504,$J17))) | H17: =IF($J17="","",IF(ISBLANK(INDEX('Product Backlog'!$H$5:$H$504,$J17)),"",INDEX('Product Backlog'!$H$5:$H$504,$J17))) | I17: =IF($J17="","",IF(ISBLANK(INDEX('Product Backlog'!$I$5:$I$504,$J17)),"",INDEX('Product Backlog'!$I$5:$I$504,$J17))) | J17: =IFERROR(MATCH($B$4&"-"&ROWS($A$10:A17),'Product Backlog'!$J$5:$J$504,0),"")
A18: =IF($J18="","",IF(ISBLANK(INDEX('Product Backlog'!$A$5:$A$504,$J18)),"",INDEX('Product Backlog'!$A$5:$A$504,$J18))) | B18: =IF($J18="","",IF(ISBLANK(INDEX('Product Backlog'!$B$5:$B$504,$J18)),"",INDEX('Product Backlog'!$B$5:$B$504,$J18))) | C18: =IF($J18="","",IF(ISBLANK(INDEX('Product Backlog'!$C$5:$C$504,$J18)),"",INDEX('Product Backlog'!$C$5:$C$504,$J18))) | D18: =IF($J18="","",IF(ISBLANK(INDEX('Product Backlog'!$D$5:$D$504,$J18)),"",INDEX('Product Backlog'!$D$5:$D$504,$J18))) | E18: =IF($J18="","",IF(ISBLANK(INDEX('Product Backlog'!$E$5:$E$504,$J18)),"",INDEX('Product Backlog'!$E$5:$E$504,$J18))) | F18: =IF($J18="","",IF(ISBLANK(INDEX('Product Backlog'!$F$5:$F$504,$J18)),"",INDEX('Product Backlog'!$F$5:$F$504,$J18))) | G18: =IF($J18="","",IF(ISBLANK(INDEX('Product Backlog'!$G$5:$G$504,$J18)),"",INDEX('Product Backlog'!$G$5:$G$504,$J18))) | H18: =IF($J18="","",IF(ISBLANK(INDEX('Product Backlog'!$H$5:$H$504,$J18)),"",INDEX('Product Backlog'!$H$5:$H$504,$J18))) | I18: =IF($J18="","",IF(ISBLANK(INDEX('Product Backlog'!$I$5:$I$504,$J18)),"",INDEX('Product Backlog'!$I$5:$I$504,$J18))) | J18: =IFERROR(MATCH($B$4&"-"&ROWS($A$10:A18),'Product Backlog'!$J$5:$J$504,0),"")
A19: =IF($J19="","",IF(ISBLANK(INDEX('Product Backlog'!$A$5:$A$504,$J19)),"",INDEX('Product Backlog'!$A$5:$A$504,$J19))) | B19: =IF($J19="","",IF(ISBLANK(INDEX('Product Backlog'!$B$5:$B$504,$J19)),"",INDEX('Product Backlog'!$B$5:$B$504,$J19))) | C19: =IF($J19="","",IF(ISBLANK(INDEX('Product Backlog'!$C$5:$C$504,$J19)),"",INDEX('Product Backlog'!$C$5:$C$504,$J19))) | D19: =IF($J19="","",IF(ISBLANK(INDEX('Product Backlog'!$D$5:$D$504,$J19)),"",INDEX('Product Backlog'!$D$5:$D$504,$J19))) | E19: =IF($J19="","",IF(ISBLANK(INDEX('Product Backlog'!$E$5:$E$504,$J19)),"",INDEX('Product Backlog'!$E$5:$E$504,$J19))) | F19: =IF($J19="","",IF(ISBLANK(INDEX('Product Backlog'!$F$5:$F$504,$J19)),"",INDEX('Product Backlog'!$F$5:$F$504,$J19))) | G19: =IF($J19="","",IF(ISBLANK(INDEX('Product Backlog'!$G$5:$G$504,$J19)),"",INDEX('Product Backlog'!$G$5:$G$504,$J19))) | H19: =IF($J19="","",IF(ISBLANK(INDEX('Product Backlog'!$H$5:$H$504,$J19)),"",INDEX('Product Backlog'!$H$5:$H$504,$J19))) | I19: =IF($J19="","",IF(ISBLANK(INDEX('Product Backlog'!$I$5:$I$504,$J19)),"",INDEX('Product Backlog'!$I$5:$I$504,$J19))) | J19: =IFERROR(MATCH($B$4&"-"&ROWS($A$10:A19),'Product Backlog'!$J$5:$J$504,0),"")
A20: =IF($J20="","",IF(ISBLANK(INDEX('Product Backlog'!$A$5:$A$504,$J20)),"",INDEX('Product Backlog'!$A$5:$A$504,$J20))) | B20: =IF($J20="","",IF(ISBLANK(INDEX('Product Backlog'!$B$5:$B$504,$J20)),"",INDEX('Product Backlog'!$B$5:$B$504,$J20))) | C20: =IF($J20="","",IF(ISBLANK(INDEX('Product Backlog'!$C$5:$C$504,$J20)),"",INDEX('Product Backlog'!$C$5:$C$504,$J20))) | D20: =IF($J20="","",IF(ISBLANK(INDEX('Product Backlog'!$D$5:$D$504,$J20)),"",INDEX('Product Backlog'!$D$5:$D$504,$J20))) | E20: =IF($J20="","",IF(ISBLANK(INDEX('Product Backlog'!$E$5:$E$504,$J20)),"",INDEX('Product Backlog'!$E$5:$E$504,$J20))) | F20: =IF($J20="","",IF(ISBLANK(INDEX('Product Backlog'!$F$5:$F$504,$J20)),"",INDEX('Product Backlog'!$F$5:$F$504,$J20))) | G20: =IF($J20="","",IF(ISBLANK(INDEX('Product Backlog'!$G$5:$G$504,$J20)),"",INDEX('Product Backlog'!$G$5:$G$504,$J20))) | H20: =IF($J20="","",IF(ISBLANK(INDEX('Product Backlog'!$H$5:$H$504,$J20)),"",INDEX('Product Backlog'!$H$5:$H$504,$J20))) | I20: =IF($J20="","",IF(ISBLANK(INDEX('Product Backlog'!$I$5:$I$504,$J20)),"",INDEX('Product Backlog'!$I$5:$I$504,$J20))) | J20: =IFERROR(MATCH($B$4&"-"&ROWS($A$10:A20),'Product Backlog'!$J$5:$J$504,0),"")
A21: =IF($J21="","",IF(ISBLANK(INDEX('Product Backlog'!$A$5:$A$504,$J21)),"",INDEX('Product Backlog'!$A$5:$A$504,$J21))) | B21: =IF($J21="","",IF(ISBLANK(INDEX('Product Backlog'!$B$5:$B$504,$J21)),"",INDEX('Product Backlog'!$B$5:$B$504,$J21))) | C21: =IF($J21="","",IF(ISBLANK(INDEX('Product Backlog'!$C$5:$C$504,$J21)),"",INDEX('Product Backlog'!$C$5:$C$504,$J21))) | D21: =IF($J21="","",IF(ISBLANK(INDEX('Product Backlog'!$D$5:$D$504,$J21)),"",INDEX('Product Backlog'!$D$5:$D$504,$J21))) | E21: =IF($J21="","",IF(ISBLANK(INDEX('Product Backlog'!$E$5:$E$504,$J21)),"",INDEX('Product Backlog'!$E$5:$E$504,$J21))) | F21: =IF($J21="","",IF(ISBLANK(INDEX('Product Backlog'!$F$5:$F$504,$J21)),"",INDEX('Product Backlog'!$F$5:$F$504,$J21))) | G21: =IF($J21="","",IF(ISBLANK(INDEX('Product Backlog'!$G$5:$G$504,$J21)),"",INDEX('Product Backlog'!$G$5:$G$504,$J21))) | H21: =IF($J21="","",IF(ISBLANK(INDEX('Product Backlog'!$H$5:$H$504,$J21)),"",INDEX('Product Backlog'!$H$5:$H$504,$J21))) | I21: =IF($J21="","",IF(ISBLANK(INDEX('Product Backlog'!$I$5:$I$504,$J21)),"",INDEX('Product Backlog'!$I$5:$I$504,$J21))) | J21: =IFERROR(MATCH($B$4&"-"&ROWS($A$10:A21),'Product Backlog'!$J$5:$J$504,0),"")
A22: =IF($J22="","",IF(ISBLANK(INDEX('Product Backlog'!$A$5:$A$504,$J22)),"",INDEX('Product Backlog'!$A$5:$A$504,$J22))) | B22: =IF($J22="","",IF(ISBLANK(INDEX('Product Backlog'!$B$5:$B$504,$J22)),"",INDEX('Product Backlog'!$B$5:$B$504,$J22))) | C22: =IF($J22="","",IF(ISBLANK(INDEX('Product Backlog'!$C$5:$C$504,$J22)),"",INDEX('Product Backlog'!$C$5:$C$504,$J22))) | D22: =IF($J22="","",IF(ISBLANK(INDEX('Product Backlog'!$D$5:$D$504,$J22)),"",INDEX('Product Backlog'!$D$5:$D$504,$J22))) | E22: =IF($J22="","",IF(ISBLANK(INDEX('Product Backlog'!$E$5:$E$504,$J22)),"",INDEX('Product Backlog'!$E$5:$E$504,$J22))) | F22: =IF($J22="","",IF(ISBLANK(INDEX('Product Backlog'!$F$5:$F$504,$J22)),"",INDEX('Product Backlog'!$F$5:$F$504,$J22))) | G22: =IF($J22="","",IF(ISBLANK(INDEX('Product Backlog'!$G$5:$G$504,$J22)),"",INDEX('Product Backlog'!$G$5:$G$504,$J22))) | H22: =IF($J22="","",IF(ISBLANK(INDEX('Product Backlog'!$H$5:$H$504,$J22)),"",INDEX('Product Backlog'!$H$5:$H$504,$J22))) | I22: =IF($J22="","",IF(ISBLANK(INDEX('Product Backlog'!$I$5:$I$504,$J22)),"",INDEX('Product Backlog'!$I$5:$I$504,$J22))) | J22: =IFERROR(MATCH($B$4&"-"&ROWS($A$10:A22),'Product Backlog'!$J$5:$J$504,0),"")
A23: =IF($J23="","",IF(ISBLANK(INDEX('Product Backlog'!$A$5:$A$504,$J23)),"",INDEX('Product Backlog'!$A$5:$A$504,$J23))) | B23: =IF($J23="","",IF(ISBLANK(INDEX('Product Backlog'!$B$5:$B$504,$J23)),"",INDEX('Product Backlog'!$B$5:$B$504,$J23))) | C23: =IF($J23="","",IF(ISBLANK(INDEX('Product Backlog'!$C$5:$C$504,$J23)),"",INDEX('Product Backlog'!$C$5:$C$504,$J23))) | D23: =IF($J23="","",IF(ISBLANK(INDEX('Product Backlog'!$D$5:$D$504,$J23)),"",INDEX('Product Backlog'!$D$5:$D$504,$J23))) | E23: =IF($J23="","",IF(ISBLANK(INDEX('Product Backlog'!$E$5:$E$504,$J23)),"",INDEX('Product Backlog'!$E$5:$E$504,$J23))) | F23: =IF($J23="","",IF(ISBLANK(INDEX('Product Backlog'!$F$5:$F$504,$J23)),"",INDEX('Product Backlog'!$F$5:$F$504,$J23))) | G23: =IF($J23="","",IF(ISBLANK(INDEX('Product Backlog'!$G$5:$G$504,$J23)),"",INDEX('Product Backlog'!$G$5:$G$504,$J23))) | H23: =IF($J23="","",IF(ISBLANK(INDEX('Product Backlog'!$H$5:$H$504,$J23)),"",INDEX('Product Backlog'!$H$5:$H$504,$J23))) | I23: =IF($J23="","",IF(ISBLANK(INDEX('Product Backlog'!$I$5:$I$504,$J23)),"",INDEX('Product Backlog'!$I$5:$I$504,$J23))) | J23: =IFERROR(MATCH($B$4&"-"&ROWS($A$10:A23),'Product Backlog'!$J$5:$J$504,0),"")
... A109: =IF($J109="","",IF(ISBLANK(INDEX('Product Backlog'!$A$5:$A$504,$J109)),"",INDEX('Product Backlog'!$A$5:$A$504,$J109))) | B109: =IF($J109="","",IF(ISBLANK(INDEX('Product Backlog'!$B$5:$B$504,$J109)),"",INDEX('Product Backlog'!$B$5:$B$504,$J109))) | C109: =IF($J109="","",IF(ISBLANK(INDEX('Product Backlog'!$C$5:$C$504,$J109)),"",INDEX('Product Backlog'!$C$5:$C$504,$J109))) | D109: =IF($J109="","",IF(ISBLANK(INDEX('Product Backlog'!$D$5:$D$504,$J109)),"",INDEX('Product Backlog'!$D$5:$D$504,$J109))) | E109: =IF($J109="","",IF(ISBLANK(INDEX('Product Backlog'!$E$5:$E$504,$J109)),"",INDEX('Product Backlog'!$E$5:$E$504,$J109))) | F109: =IF($J109="","",IF(ISBLANK(INDEX('Product Backlog'!$F$5:$F$504,$J109)),"",INDEX('Product Backlog'!$F$5:$F$504,$J109))) | G109: =IF($J109="","",IF(ISBLANK(INDEX('Product Backlog'!$G$5:$G$504,$J109)),"",INDEX('Product Backlog'!$G$5:$G$504,$J109))) | H109: =IF($J109="","",IF(ISBLANK(INDEX('Product Backlog'!$H$5:$H$504,$J109)),"",INDEX('Product Backlog'!$H$5:$H$504,$J109))) | I109: =IF($J109="","",IF(ISBLANK(INDEX('Product Backlog'!$I$5:$I$504,$J109)),"",INDEX('Product Backlog'!$I$5:$I$504,$J109))) | J109: =IFERROR(MATCH($B$4&"-"&ROWS($A$10:A109),'Product Backlog'!$J$5:$J$504,0),"")

Sheet Sprint 2
A1: Sprint 2
A2: Sprint 2 records and backlog view. Edit task details on the Product Backlog sheet; this view updates from the Sprint #.
A4: Sprint # | B4: 2 | D4: Start date | E4: 46288 | G4: End date | H4: 46297
A5: Sprint goal | B5: Build the German-language toggle and a country-aware filing-search prototype for U.S. and German companies.
A7: Tasks | B7: =COUNTIFS('Product Backlog'!$B$5:$B$504,2,'Product Backlog'!$C$5:$C$504,"<>") -> 3 | C7: Completed | D7: =COUNTIFS('Product Backlog'!$B$5:$B$504,2,'Product Backlog'!$D$5:$D$504,"Done")+COUNTIFS('Product Backlog'!$B$5:$B$504,2,'Product Backlog'!$D$5:$D$504,"Completed") -> 3 | E7: Hours logged | F7: =SUMIFS('Product Backlog'!$H$5:$H$504,'Product Backlog'!$B$5:$B$504,2) -> 7.5 | G7: Work points | H7: =SUMIFS('Product Backlog'!$I$5:$I$504,'Product Backlog'!$B$5:$B$504,2) -> 140
A8: Auto-generated view. Do not enter tasks here; add or change them on Product Backlog.
A9: Task # | B9: Sprint # | C9: Task description | D9: Status | E9: Maintainer | F9: Date added | G9: Date completed | H9: Hours to complete | I9: Work points assigned
A10: =IF($J10="","",IF(ISBLANK(INDEX('Product Backlog'!$A$5:$A$504,$J10)),"",INDEX('Product Backlog'!$A$5:$A$504,$J10))) -> 4 | B10: =IF($J10="","",IF(ISBLANK(INDEX('Product Backlog'!$B$5:$B$504,$J10)),"",INDEX('Product Backlog'!$B$5:$B$504,$J10))) -> 2 | C10: =IF($J10="","",IF(ISBLANK(INDEX('Product Backlog'!$C$5:H17,$J10)),"",INDEX('Product Backlog'!$C$5:$C$504,$J10))) -> German language toggle | D10: =IF($J10="","",IF(ISBLANK(INDEX('Product Backlog'!$D$5:$D$504,$J10)),"",INDEX('Product Backlog'!$D$5:$D$504,$J10))) -> Completed | E10: chropic | F10: 46277 | G10: =IF($J10="","",IF(ISBLANK(INDEX('Product Backlog'!$G$5:$G$504,$J10)),"",INDEX('Product Backlog'!$G$5:$G$504,$J10))) -> 46293 | H10: 1 | I10: =IF($J10="","",IF(ISBLANK(INDEX('Product Backlog'!$I$5:$I$504,$J10)),"",INDEX('Product Backlog'!$I$5:$I$504,$J10))) -> 45 | J10: =IFERROR(MATCH($B$4&"-"&ROWS($A$10:A10),'Product Backlog'!$J$5:$J$504,0),"") -> 4
A11: =IF($J11="","",IF(ISBLANK(INDEX('Product Backlog'!$A$5:$A$504,$J11)),"",INDEX('Product Backlog'!$A$5:$A$504,$J11))) -> 5 | B11: =IF($J11="","",IF(ISBLANK(INDEX('Product Backlog'!$B$5:$B$504,$J11)),"",INDEX('Product Backlog'!$B$5:$B$504,$J11))) -> 2 | C11: =IF($J11="","",IF(ISBLANK(INDEX('Product Backlog'!$C$5:$C$504,$J11)),"",INDEX('Product Backlog'!$C$5:$C$504,$J11))) -> Updated Search Feature (Frontend) | D11: =IF($J11="","",IF(ISBLANK(INDEX('Product Backlog'!$D$5:$D$504,$J11)),"",INDEX('Product Backlog'!$D$5:$D$504,$J11))) -> Completed | E11: =IF($J11="","",IF(ISBLANK(INDEX('Product Backlog'!$E$5:$E$504,$J11)),"",INDEX('Product Backlog'!$E$5:$E$504,$J11))) -> oogwaysprophecy732 | F11: =IF($J11="","",IF(ISBLANK(INDEX('Product Backlog'!$F$5:$F$504,$J11)),"",INDEX('Product Backlog'!$F$5:$F$504,$J11))) -> 46288 | G11: =IF($J11="","",IF(ISBLANK(INDEX('Product Backlog'!$G$5:$G$504,$J11)),"",INDEX('Product Backlog'!$G$5:$G$504,$J11))) -> 46288 | H11: 3 | I11: =IF($J11="","",IF(ISBLANK(INDEX('Product Backlog'!$I$5:$I$504,$J11)),"",INDEX('Product Backlog'!$I$5:$I$504,$J11))) -> 45 | J11: =IFERROR(MATCH($B$4&"-"&ROWS($A$10:A11),'Product Backlog'!$J$5:$J$504,0),"") -> 5
A12: =IF($J12="","",IF(ISBLANK(INDEX('Product Backlog'!$A$5:$A$504,$J12)),"",INDEX('Product Backlog'!$A$5:$A$504,$J12))) -> 6 | B12: =IF($J12="","",IF(ISBLANK(INDEX('Product Backlog'!$B$5:$B$504,$J12)),"",INDEX('Product Backlog'!$B$5:$B$504,$J12))) -> 2 | C12: =IF($J12="","",IF(ISBLANK(INDEX('Product Backlog'!$C$5:$C$504,$J12)),"",INDEX('Product Backlog'!$C$5:$C$504,$J12))) -> Server-side RSS Feed | D12: =IF($J12="","",IF(ISBLANK(INDEX('Product Backlog'!$D$5:$D$504,$J12)),"",INDEX('Product Backlog'!$D$5:$D$504,$J12))) -> Completed | E12: chropic | F12: 46288 | G12: 46290 | H12: 2 | I12: 15 | J12: =IFERROR(MATCH($B$4&"-"&ROWS($A$10:A12),'Product Backlog'!$J$5:$J$504,0),"") -> 6
A13: =IF($J13="","",IF(ISBLANK(INDEX('Product Backlog'!$A$5:$A$504,$J13)),"",INDEX('Product Backlog'!$A$5:$A$504,$J13))) | B13: =IF($J13="","",IF(ISBLANK(INDEX('Product Backlog'!$B$5:$B$504,$J13)),"",INDEX('Product Backlog'!$B$5:$B$504,$J13))) | C13: =IF($J13="","",IF(ISBLANK(INDEX('Product Backlog'!$C$5:$C$504,$J13)),"",INDEX('Product Backlog'!$C$5:$C$504,$J13))) | D13: =IF($J13="","",IF(ISBLANK(INDEX('Product Backlog'!$D$5:$D$504,$J13)),"",INDEX('Product Backlog'!$D$5:$D$504,$J13))) | E13: =IF($J13="","",IF(ISBLANK(INDEX('Product Backlog'!$E$5:$E$504,$J13)),"",INDEX('Product Backlog'!$E$5:$E$504,$J13))) | F13: =IF($J13="","",IF(ISBLANK(INDEX('Product Backlog'!$F$5:$F$504,$J13)),"",INDEX('Product Backlog'!$F$5:$F$504,$J13))) | G13: =IF($J13="","",IF(ISBLANK(INDEX('Product Backlog'!$G$5:$G$504,$J13)),"",INDEX('Product Backlog'!$G$5:$G$504,$J13))) | H13: =IF($J13="","",IF(ISBLANK(INDEX('Product Backlog'!$H$5:$H$504,$J13)),"",INDEX('Product Backlog'!$H$5:$H$504,$J13))) | I13: =IF($J13="","",IF(ISBLANK(INDEX('Product Backlog'!$I$5:$I$504,$J13)),"",INDEX('Product Backlog'!$I$5:$I$504,$J13))) | J13: =IFERROR(MATCH($B$4&"-"&ROWS($A$10:A13),'Product Backlog'!$J$5:$J$504,0),"")
A14: =IF($J14="","",IF(ISBLANK(INDEX('Product Backlog'!$A$5:$A$504,$J14)),"",INDEX('Product Backlog'!$A$5:$A$504,$J14))) | B14: =IF($J14="","",IF(ISBLANK(INDEX('Product Backlog'!$B$5:$B$504,$J14)),"",INDEX('Product Backlog'!$B$5:$B$504,$J14))) | C14: =IF($J14="","",IF(ISBLANK(INDEX('Product Backlog'!$C$5:$C$504,$J14)),"",INDEX('Product Backlog'!$C$5:$C$504,$J14))) | D14: =IF($J14="","",IF(ISBLANK(INDEX('Product Backlog'!$D$5:$D$504,$J14)),"",INDEX('Product Backlog'!$D$5:$D$504,$J14))) | E14: =IF($J14="","",IF(ISBLANK(INDEX('Product Backlog'!$E$5:$E$504,$J14)),"",INDEX('Product Backlog'!$E$5:$E$504,$J14))) | F14: =IF($J14="","",IF(ISBLANK(INDEX('Product Backlog'!$F$5:$F$504,$J14)),"",INDEX('Product Backlog'!$F$5:$F$504,$J14))) | G14: =IF($J14="","",IF(ISBLANK(INDEX('Product Backlog'!$G$5:$G$504,$J14)),"",INDEX('Product Backlog'!$G$5:$G$504,$J14))) | H14: =IF($J14="","",IF(ISBLANK(INDEX('Product Backlog'!$H$5:$H$504,$J14)),"",INDEX('Product Backlog'!$H$5:$H$504,$J14))) | I14: =IF($J14="","",IF(ISBLANK(INDEX('Product Backlog'!$I$5:$I$504,$J14)),"",INDEX('Product Backlog'!$I$5:$I$504,$J14))) | J14: =IFERROR(MATCH($B$4&"-"&ROWS($A$10:A14),'Product Backlog'!$J$5:$J$504,0),"")
A15: =IF($J15="","",IF(ISBLANK(INDEX('Product Backlog'!$A$5:$A$504,$J15)),"",INDEX('Product Backlog'!$A$5:$A$504,$J15))) | B15: =IF($J15="","",IF(ISBLANK(INDEX('Product Backlog'!$B$5:$B$504,$J15)),"",INDEX('Product Backlog'!$B$5:$B$504,$J15))) | C15: =IF($J15="","",IF(ISBLANK(INDEX('Product Backlog'!$C$5:$C$504,$J15)),"",INDEX('Product Backlog'!$C$5:$C$504,$J15))) | D15: =IF($J15="","",IF(ISBLANK(INDEX('Product Backlog'!$D$5:$D$504,$J15)),"",INDEX('Product Backlog'!$D$5:$D$504,$J15))) | E15: =IF($J15="","",IF(ISBLANK(INDEX('Product Backlog'!$E$5:$E$504,$J15)),"",INDEX('Product Backlog'!$E$5:$E$504,$J15))) | F15: =IF($J15="","",IF(ISBLANK(INDEX('Product Backlog'!$F$5:$F$504,$J15)),"",INDEX('Product Backlog'!$F$5:$F$504,$J15))) | G15: =IF($J15="","",IF(ISBLANK(INDEX('Product Backlog'!$G$5:$G$504,$J15)),"",INDEX('Product Backlog'!$G$5:$G$504,$J15))) | H15: =IF($J15="","",IF(ISBLANK(INDEX('Product Backlog'!$H$5:$H$504,$J15)),"",INDEX('Product Backlog'!$H$5:$H$504,$J15))) | I15: =IF($J15="","",IF(ISBLANK(INDEX('Product Backlog'!$I$5:$I$504,$J15)),"",INDEX('Product Backlog'!$I$5:$I$504,$J15))) | J15: =IFERROR(MATCH($B$4&"-"&ROWS($A$10:A15),'Product Backlog'!$J$5:$J$504,0),"")
A16: =IF($J16="","",IF(ISBLANK(INDEX('Product Backlog'!$A$5:$A$504,$J16)),"",INDEX('Product Backlog'!$A$5:$A$504,$J16))) | B16: =IF($J16="","",IF(ISBLANK(INDEX('Product Backlog'!$B$5:$B$504,$J16)),"",INDEX('Product Backlog'!$B$5:$B$504,$J16))) | C16: =IF($J16="","",IF(ISBLANK(INDEX('Product Backlog'!$C$5:$C$504,$J16)),"",INDEX('Product Backlog'!$C$5:$C$504,$J16))) | D16: =IF($J16="","",IF(ISBLANK(INDEX('Product Backlog'!$D$5:$D$504,$J16)),"",INDEX('Product Backlog'!$D$5:$D$504,$J16))) | E16: =IF($J16="","",IF(ISBLANK(INDEX('Product Backlog'!$E$5:$E$504,$J16)),"",INDEX('Product Backlog'!$E$5:$E$504,$J16))) | F16: =IF($J16="","",IF(ISBLANK(INDEX('Product Backlog'!$F$5:$F$504,$J16)),"",INDEX('Product Backlog'!$F$5:$F$504,$J16))) | G16: =IF($J16="","",IF(ISBLANK(INDEX('Product Backlog'!$G$5:$G$504,$J16)),"",INDEX('Product Backlog'!$G$5:$G$504,$J16))) | H16: =IF($J16="","",IF(ISBLANK(INDEX('Product Backlog'!$H$5:$H$504,$J16)),"",INDEX('Product Backlog'!$H$5:$H$504,$J16))) | I16: =IF($J16="","",IF(ISBLANK(INDEX('Product Backlog'!$I$5:$I$504,$J16)),"",INDEX('Product Backlog'!$I$5:$I$504,$J16))) | J16: =IFERROR(MATCH($B$4&"-"&ROWS($A$10:A16),'Product Backlog'!$J$5:$J$504,0),"")
A17: =IF($J17="","",IF(ISBLANK(INDEX('Product Backlog'!$A$5:$A$504,$J17)),"",INDEX('Product Backlog'!$A$5:$A$504,$J17))) | B17: =IF($J17="","",IF(ISBLANK(INDEX('Product Backlog'!$B$5:$B$504,$J17)),"",INDEX('Product Backlog'!$B$5:$B$504,$J17))) | C17: =IF($J17="","",IF(ISBLANK(INDEX('Product Backlog'!$C$5:$C$504,$J17)),"",INDEX('Product Backlog'!$C$5:$C$504,$J17))) | D17: =IF($J17="","",IF(ISBLANK(INDEX('Product Backlog'!$D$5:$D$504,$J17)),"",INDEX('Product Backlog'!$D$5:$D$504,$J17))) | E17: =IF($J17="","",IF(ISBLANK(INDEX('Product Backlog'!$E$5:$E$504,$J17)),"",INDEX('Product Backlog'!$E$5:$E$504,$J17))) | F17: =IF($J17="","",IF(ISBLANK(INDEX('Product Backlog'!$F$5:$F$504,$J17)),"",INDEX('Product Backlog'!$F$5:$F$504,$J17))) | G17: =IF($J17="","",IF(ISBLANK(INDEX('Product Backlog'!$G$5:$G$504,$J17)),"",INDEX('Product Backlog'!$G$5:$G$504,$J17))) | H17: =IF($J17="","",IF(ISBLANK(INDEX('Product Backlog'!$H$5:$H$504,$J17)),"",INDEX('Product Backlog'!$H$5:$H$504,$J17))) | I17: =IF($J17="","",IF(ISBLANK(INDEX('Product Backlog'!$I$5:$I$504,$J17)),"",INDEX('Product Backlog'!$I$5:$I$504,$J17))) | J17: =IFERROR(MATCH($B$4&"-"&ROWS($A$10:A17),'Product Backlog'!$J$5:$J$504,0),"")
A18: =IF($J18="","",IF(ISBLANK(INDEX('Product Backlog'!$A$5:$A$504,$J18)),"",INDEX('Product Backlog'!$A$5:$A$504,$J18))) | B18: =IF($J18="","",IF(ISBLANK(INDEX('Product Backlog'!$B$5:$B$504,$J18)),"",INDEX('Product Backlog'!$B$5:$B$504,$J18))) | C18: =IF($J18="","",IF(ISBLANK(INDEX('Product Backlog'!$C$5:$C$504,$J18)),"",INDEX('Product Backlog'!$C$5:$C$504,$J18))) | D18: =IF($J18="","",IF(ISBLANK(INDEX('Product Backlog'!$D$5:$D$504,$J18)),"",INDEX('Product Backlog'!$D$5:$D$504,$J18))) | E18: =IF($J18="","",IF(ISBLANK(INDEX('Product Backlog'!$E$5:$E$504,$J18)),"",INDEX('Product Backlog'!$E$5:$E$504,$J18))) | F18: =IF($J18="","",IF(ISBLANK(INDEX('Product Backlog'!$F$5:$F$504,$J18)),"",INDEX('Product Backlog'!$F$5:$F$504,$J18))) | G18: =IF($J18="","",IF(ISBLANK(INDEX('Product Backlog'!$G$5:$G$504,$J18)),"",INDEX('Product Backlog'!$G$5:$G$504,$J18))) | H18: =IF($J18="","",IF(ISBLANK(INDEX('Product Backlog'!$H$5:$H$504,$J18)),"",INDEX('Product Backlog'!$H$5:$H$504,$J18))) | I18: =IF($J18="","",IF(ISBLANK(INDEX('Product Backlog'!$I$5:$I$504,$J18)),"",INDEX('Product Backlog'!$I$5:$I$504,$J18))) | J18: =IFERROR(MATCH($B$4&"-"&ROWS($A$10:A18),'Product Backlog'!$J$5:$J$504,0),"")
A19: =IF($J19="","",IF(ISBLANK(INDEX('Product Backlog'!$A$5:$A$504,$J19)),"",INDEX('Product Backlog'!$A$5:$A$504,$J19))) | B19: =IF($J19="","",IF(ISBLANK(INDEX('Product Backlog'!$B$5:$B$504,$J19)),"",INDEX('Product Backlog'!$B$5:$B$504,$J19))) | C19: =IF($J19="","",IF(ISBLANK(INDEX('Product Backlog'!$C$5:$C$504,$J19)),"",INDEX('Product Backlog'!$C$5:$C$504,$J19))) | D19: =IF($J19="","",IF(ISBLANK(INDEX('Product Backlog'!$D$5:$D$504,$J19)),"",INDEX('Product Backlog'!$D$5:$D$504,$J19))) | E19: =IF($J19="","",IF(ISBLANK(INDEX('Product Backlog'!$E$5:$E$504,$J19)),"",INDEX('Product Backlog'!$E$5:$E$504,$J19))) | F19: =IF($J19="","",IF(ISBLANK(INDEX('Product Backlog'!$F$5:$F$504,$J19)),"",INDEX('Product Backlog'!$F$5:$F$504,$J19))) | G19: =IF($J19="","",IF(ISBLANK(INDEX('Product Backlog'!$G$5:$G$504,$J19)),"",INDEX('Product Backlog'!$G$5:$G$504,$J19))) | H19: =IF($J19="","",IF(ISBLANK(INDEX('Product Backlog'!$H$5:$H$504,$J19)),"",INDEX('Product Backlog'!$H$5:$H$504,$J19))) | I19: =IF($J19="","",IF(ISBLANK(INDEX('Product Backlog'!$I$5:$I$504,$J19)),"",INDEX('Product Backlog'!$I$5:$I$504,$J19))) | J19: =IFERROR(MATCH($B$4&"-"&ROWS($A$10:A19),'Product Backlog'!$J$5:$J$504,0),"")
